2017-02-19 15:35:54,191 [Thread-2:139815498323712] [django.request:124] [ERROR]- Internal Server Error: /index
Traceback (most recent call last):
  File "/usr/local/lib/python3.5/dist-packages/django/core/handlers/exception.py", line 39, in inner
    response = get_response(request)
  File "/usr/local/lib/python3.5/dist-packages/django/core/handlers/base.py", line 187, in _get_response
    response = self.process_exception_by_middleware(e, request)
  File "/usr/local/lib/python3.5/dist-packages/django/core/handlers/base.py", line 185, in _get_response
    response = wrapped_callback(request, *callback_args, **callback_kwargs)
  File "/home/nborn/reading_notes/python_web/mazi/django_3_进阶/blog_django/blog/views.py", line 17, in index
    return render(request,'index.html',locals())
  File "/usr/local/lib/python3.5/dist-packages/django/shortcuts.py", line 30, in render
    content = loader.render_to_string(template_name, context, request, using=using)
  File "/usr/local/lib/python3.5/dist-packages/django/template/loader.py", line 68, in render_to_string
    return template.render(context, request)
  File "/usr/local/lib/python3.5/dist-packages/django/template/backends/django.py", line 66, in render
    return self.template.render(context)
  File "/usr/local/lib/python3.5/dist-packages/django/template/base.py", line 206, in render
    with context.bind_template(self):
  File "/usr/lib/python3.5/contextlib.py", line 59, in __enter__
    return next(self.gen)
  File "/usr/local/lib/python3.5/dist-packages/django/template/context.py", line 236, in bind_template
    updates.update(processor(self.request))
TypeError: global_setting() takes 0 positional arguments but 1 was given
2017-02-19 15:39:11,035 [Thread-2:140296180463360] [django.request:124] [ERROR]- Internal Server Error: /index
Traceback (most recent call last):
  File "/usr/local/lib/python3.5/dist-packages/django/core/handlers/exception.py", line 39, in inner
    response = get_response(request)
  File "/usr/local/lib/python3.5/dist-packages/django/core/handlers/base.py", line 187, in _get_response
    response = self.process_exception_by_middleware(e, request)
  File "/usr/local/lib/python3.5/dist-packages/django/core/handlers/base.py", line 185, in _get_response
    response = wrapped_callback(request, *callback_args, **callback_kwargs)
  File "/home/nborn/reading_notes/python_web/mazi/django_3_进阶/blog_django/blog/views.py", line 17, in index
    return render(request,'index.html',locals())
  File "/usr/local/lib/python3.5/dist-packages/django/shortcuts.py", line 30, in render
    content = loader.render_to_string(template_name, context, request, using=using)
  File "/usr/local/lib/python3.5/dist-packages/django/template/loader.py", line 68, in render_to_string
    return template.render(context, request)
  File "/usr/local/lib/python3.5/dist-packages/django/template/backends/django.py", line 66, in render
    return self.template.render(context)
  File "/usr/local/lib/python3.5/dist-packages/django/template/base.py", line 206, in render
    with context.bind_template(self):
  File "/usr/lib/python3.5/contextlib.py", line 59, in __enter__
    return next(self.gen)
  File "/usr/local/lib/python3.5/dist-packages/django/template/context.py", line 236, in bind_template
    updates.update(processor(self.request))
TypeError: global_setting() takes 0 positional arguments but 1 was given
2017-02-20 02:02:52,117 [Thread-25:139933676312320] [django.request:124] [ERROR]- Internal Server Error: /admin/blog/article/add/
Traceback (most recent call last):
  File "/usr/local/lib/python3.5/dist-packages/django/db/backends/utils.py", line 64, in execute
    return self.cursor.execute(sql, params)
  File "/usr/local/lib/python3.5/dist-packages/django/db/backends/mysql/base.py", line 110, in execute
    return self.cursor.execute(query, args)
  File "/home/nborn/.local/lib/python3.5/site-packages/pymysql/cursors.py", line 166, in execute
    result = self._query(query)
  File "/home/nborn/.local/lib/python3.5/site-packages/pymysql/cursors.py", line 322, in _query
    conn.query(q)
  File "/home/nborn/.local/lib/python3.5/site-packages/pymysql/connections.py", line 852, in query
    self._affected_rows = self._read_query_result(unbuffered=unbuffered)
  File "/home/nborn/.local/lib/python3.5/site-packages/pymysql/connections.py", line 1053, in _read_query_result
    result.read()
  File "/home/nborn/.local/lib/python3.5/site-packages/pymysql/connections.py", line 1336, in read
    first_packet = self.connection._read_packet()
  File "/home/nborn/.local/lib/python3.5/site-packages/pymysql/connections.py", line 1010, in _read_packet
    packet.check_error()
  File "/home/nborn/.local/lib/python3.5/site-packages/pymysql/connections.py", line 393, in check_error
    err.raise_mysql_exception(self._data)
  File "/home/nborn/.local/lib/python3.5/site-packages/pymysql/err.py", line 107, in raise_mysql_exception
    raise errorclass(errno, errval)
pymysql.err.IntegrityError: (1048, "Column 'user_id' cannot be null")

The above exception was the direct cause of the following exception:

Traceback (most recent call last):
  File "/usr/local/lib/python3.5/dist-packages/django/core/handlers/exception.py", line 39, in inner
    response = get_response(request)
  File "/usr/local/lib/python3.5/dist-packages/django/core/handlers/base.py", line 187, in _get_response
    response = self.process_exception_by_middleware(e, request)
  File "/usr/local/lib/python3.5/dist-packages/django/core/handlers/base.py", line 185, in _get_response
    response = wrapped_callback(request, *callback_args, **callback_kwargs)
  File "/usr/local/lib/python3.5/dist-packages/django/contrib/admin/options.py", line 544, in wrapper
    return self.admin_site.admin_view(view)(*args, **kwargs)
  File "/usr/local/lib/python3.5/dist-packages/django/utils/decorators.py", line 149, in _wrapped_view
    response = view_func(request, *args, **kwargs)
  File "/usr/local/lib/python3.5/dist-packages/django/views/decorators/cache.py", line 57, in _wrapped_view_func
    response = view_func(request, *args, **kwargs)
  File "/usr/local/lib/python3.5/dist-packages/django/contrib/admin/sites.py", line 211, in inner
    return view(request, *args, **kwargs)
  File "/usr/local/lib/python3.5/dist-packages/django/contrib/admin/options.py", line 1509, in add_view
    return self.changeform_view(request, None, form_url, extra_context)
  File "/usr/local/lib/python3.5/dist-packages/django/utils/decorators.py", line 67, in _wrapper
    return bound_func(*args, **kwargs)
  File "/usr/local/lib/python3.5/dist-packages/django/utils/decorators.py", line 149, in _wrapped_view
    response = view_func(request, *args, **kwargs)
  File "/usr/local/lib/python3.5/dist-packages/django/utils/decorators.py", line 63, in bound_func
    return func.__get__(self, type(self))(*args2, **kwargs2)
  File "/usr/lib/python3.5/contextlib.py", line 30, in inner
    return func(*args, **kwds)
  File "/usr/local/lib/python3.5/dist-packages/django/contrib/admin/options.py", line 1449, in changeform_view
    self.save_model(request, new_object, form, not add)
  File "/usr/local/lib/python3.5/dist-packages/django/contrib/admin/options.py", line 1007, in save_model
    obj.save()
  File "/usr/local/lib/python3.5/dist-packages/django/db/models/base.py", line 796, in save
    force_update=force_update, update_fields=update_fields)
  File "/usr/local/lib/python3.5/dist-packages/django/db/models/base.py", line 824, in save_base
    updated = self._save_table(raw, cls, force_insert, force_update, using, update_fields)
  File "/usr/local/lib/python3.5/dist-packages/django/db/models/base.py", line 908, in _save_table
    result = self._do_insert(cls._base_manager, using, fields, update_pk, raw)
  File "/usr/local/lib/python3.5/dist-packages/django/db/models/base.py", line 947, in _do_insert
    using=using, raw=raw)
  File "/usr/local/lib/python3.5/dist-packages/django/db/models/manager.py", line 85, in manager_method
    return getattr(self.get_queryset(), name)(*args, **kwargs)
  File "/usr/local/lib/python3.5/dist-packages/django/db/models/query.py", line 1045, in _insert
    return query.get_compiler(using=using).execute_sql(return_id)
  File "/usr/local/lib/python3.5/dist-packages/django/db/models/sql/compiler.py", line 1054, in execute_sql
    cursor.execute(sql, params)
  File "/usr/local/lib/python3.5/dist-packages/django/db/backends/utils.py", line 79, in execute
    return super(CursorDebugWrapper, self).execute(sql, params)
  File "/usr/local/lib/python3.5/dist-packages/django/db/backends/utils.py", line 64, in execute
    return self.cursor.execute(sql, params)
  File "/usr/local/lib/python3.5/dist-packages/django/db/utils.py", line 94, in __exit__
    six.reraise(dj_exc_type, dj_exc_value, traceback)
  File "/usr/local/lib/python3.5/dist-packages/django/utils/six.py", line 685, in reraise
    raise value.with_traceback(tb)
  File "/usr/local/lib/python3.5/dist-packages/django/db/backends/utils.py", line 64, in execute
    return self.cursor.execute(sql, params)
  File "/usr/local/lib/python3.5/dist-packages/django/db/backends/mysql/base.py", line 110, in execute
    return self.cursor.execute(query, args)
  File "/home/nborn/.local/lib/python3.5/site-packages/pymysql/cursors.py", line 166, in execute
    result = self._query(query)
  File "/home/nborn/.local/lib/python3.5/site-packages/pymysql/cursors.py", line 322, in _query
    conn.query(q)
  File "/home/nborn/.local/lib/python3.5/site-packages/pymysql/connections.py", line 852, in query
    self._affected_rows = self._read_query_result(unbuffered=unbuffered)
  File "/home/nborn/.local/lib/python3.5/site-packages/pymysql/connections.py", line 1053, in _read_query_result
    result.read()
  File "/home/nborn/.local/lib/python3.5/site-packages/pymysql/connections.py", line 1336, in read
    first_packet = self.connection._read_packet()
  File "/home/nborn/.local/lib/python3.5/site-packages/pymysql/connections.py", line 1010, in _read_packet
    packet.check_error()
  File "/home/nborn/.local/lib/python3.5/site-packages/pymysql/connections.py", line 393, in check_error
    err.raise_mysql_exception(self._data)
  File "/home/nborn/.local/lib/python3.5/site-packages/pymysql/err.py", line 107, in raise_mysql_exception
    raise errorclass(errno, errval)
django.db.utils.IntegrityError: (1048, "Column 'user_id' cannot be null")
2017-02-20 04:59:17,317 [Thread-2:139846944052992] [django.request:124] [ERROR]- Internal Server Error: /admin/blog/article/add/
Traceback (most recent call last):
  File "/usr/local/lib/python3.5/dist-packages/django/core/handlers/exception.py", line 39, in inner
    response = get_response(request)
  File "/usr/local/lib/python3.5/dist-packages/django/core/handlers/base.py", line 187, in _get_response
    response = self.process_exception_by_middleware(e, request)
  File "/usr/local/lib/python3.5/dist-packages/django/core/handlers/base.py", line 185, in _get_response
    response = wrapped_callback(request, *callback_args, **callback_kwargs)
  File "/usr/local/lib/python3.5/dist-packages/django/contrib/admin/options.py", line 544, in wrapper
    return self.admin_site.admin_view(view)(*args, **kwargs)
  File "/usr/local/lib/python3.5/dist-packages/django/utils/decorators.py", line 149, in _wrapped_view
    response = view_func(request, *args, **kwargs)
  File "/usr/local/lib/python3.5/dist-packages/django/views/decorators/cache.py", line 57, in _wrapped_view_func
    response = view_func(request, *args, **kwargs)
  File "/usr/local/lib/python3.5/dist-packages/django/contrib/admin/sites.py", line 211, in inner
    return view(request, *args, **kwargs)
  File "/usr/local/lib/python3.5/dist-packages/django/contrib/admin/options.py", line 1509, in add_view
    return self.changeform_view(request, None, form_url, extra_context)
  File "/usr/local/lib/python3.5/dist-packages/django/utils/decorators.py", line 67, in _wrapper
    return bound_func(*args, **kwargs)
  File "/usr/local/lib/python3.5/dist-packages/django/utils/decorators.py", line 149, in _wrapped_view
    response = view_func(request, *args, **kwargs)
  File "/usr/local/lib/python3.5/dist-packages/django/utils/decorators.py", line 63, in bound_func
    return func.__get__(self, type(self))(*args2, **kwargs2)
  File "/usr/lib/python3.5/contextlib.py", line 30, in inner
    return func(*args, **kwds)
  File "/usr/local/lib/python3.5/dist-packages/django/contrib/admin/options.py", line 1482, in changeform_view
    self.admin_site.each_context(request),
  File "/usr/local/lib/python3.5/dist-packages/django/contrib/admin/sites.py", line 284, in each_context
    'available_apps': self.get_app_list(request),
  File "/usr/local/lib/python3.5/dist-packages/django/contrib/admin/sites.py", line 451, in get_app_list
    app_dict = self._build_app_dict(request)
  File "/usr/local/lib/python3.5/dist-packages/django/contrib/admin/sites.py", line 418, in _build_app_dict
    model_dict['admin_url'] = reverse('admin:%s_%s_changelist' % info, current_app=self.name)
  File "/usr/local/lib/python3.5/dist-packages/django/urls/base.py", line 60, in reverse
    app_list = resolver.app_dict[ns]
  File "/usr/local/lib/python3.5/dist-packages/django/urls/resolvers.py", line 256, in app_dict
    self._populate()
  File "/usr/local/lib/python3.5/dist-packages/django/urls/resolvers.py", line 217, in _populate
    dict(defaults, **pattern.default_kwargs),
TypeError: type object argument after ** must be a mapping, not str
2017-02-20 04:59:44,285 [Thread-2:140289189889792] [django.request:124] [ERROR]- Internal Server Error: /admin/blog/article/add/
Traceback (most recent call last):
  File "/usr/local/lib/python3.5/dist-packages/django/core/handlers/exception.py", line 39, in inner
    response = get_response(request)
  File "/usr/local/lib/python3.5/dist-packages/django/core/handlers/base.py", line 187, in _get_response
    response = self.process_exception_by_middleware(e, request)
  File "/usr/local/lib/python3.5/dist-packages/django/core/handlers/base.py", line 185, in _get_response
    response = wrapped_callback(request, *callback_args, **callback_kwargs)
  File "/usr/local/lib/python3.5/dist-packages/django/contrib/admin/options.py", line 544, in wrapper
    return self.admin_site.admin_view(view)(*args, **kwargs)
  File "/usr/local/lib/python3.5/dist-packages/django/utils/decorators.py", line 149, in _wrapped_view
    response = view_func(request, *args, **kwargs)
  File "/usr/local/lib/python3.5/dist-packages/django/views/decorators/cache.py", line 57, in _wrapped_view_func
    response = view_func(request, *args, **kwargs)
  File "/usr/local/lib/python3.5/dist-packages/django/contrib/admin/sites.py", line 211, in inner
    return view(request, *args, **kwargs)
  File "/usr/local/lib/python3.5/dist-packages/django/contrib/admin/options.py", line 1509, in add_view
    return self.changeform_view(request, None, form_url, extra_context)
  File "/usr/local/lib/python3.5/dist-packages/django/utils/decorators.py", line 67, in _wrapper
    return bound_func(*args, **kwargs)
  File "/usr/local/lib/python3.5/dist-packages/django/utils/decorators.py", line 149, in _wrapped_view
    response = view_func(request, *args, **kwargs)
  File "/usr/local/lib/python3.5/dist-packages/django/utils/decorators.py", line 63, in bound_func
    return func.__get__(self, type(self))(*args2, **kwargs2)
  File "/usr/lib/python3.5/contextlib.py", line 30, in inner
    return func(*args, **kwds)
  File "/usr/local/lib/python3.5/dist-packages/django/contrib/admin/options.py", line 1482, in changeform_view
    self.admin_site.each_context(request),
  File "/usr/local/lib/python3.5/dist-packages/django/contrib/admin/sites.py", line 284, in each_context
    'available_apps': self.get_app_list(request),
  File "/usr/local/lib/python3.5/dist-packages/django/contrib/admin/sites.py", line 451, in get_app_list
    app_dict = self._build_app_dict(request)
  File "/usr/local/lib/python3.5/dist-packages/django/contrib/admin/sites.py", line 418, in _build_app_dict
    model_dict['admin_url'] = reverse('admin:%s_%s_changelist' % info, current_app=self.name)
  File "/usr/local/lib/python3.5/dist-packages/django/urls/base.py", line 60, in reverse
    app_list = resolver.app_dict[ns]
  File "/usr/local/lib/python3.5/dist-packages/django/urls/resolvers.py", line 256, in app_dict
    self._populate()
  File "/usr/local/lib/python3.5/dist-packages/django/urls/resolvers.py", line 217, in _populate
    dict(defaults, **pattern.default_kwargs),
TypeError: type object argument after ** must be a mapping, not str
2017-02-20 06:54:23,163 [Thread-221:140000079369984] [django.request:124] [ERROR]- Internal Server Error: /index
Traceback (most recent call last):
  File "/usr/local/lib/python3.5/dist-packages/django/core/handlers/exception.py", line 39, in inner
    response = get_response(request)
  File "/usr/local/lib/python3.5/dist-packages/django/core/handlers/base.py", line 187, in _get_response
    response = self.process_exception_by_middleware(e, request)
  File "/usr/local/lib/python3.5/dist-packages/django/core/handlers/base.py", line 185, in _get_response
    response = wrapped_callback(request, *callback_args, **callback_kwargs)
  File "/home/nborn/reading_notes/python_web/mazi/django_5_project_blog/blog_django/blog/views.py", line 17, in index
    return render(request,'index.html',locals())
  File "/usr/local/lib/python3.5/dist-packages/django/shortcuts.py", line 30, in render
    content = loader.render_to_string(template_name, context, request, using=using)
  File "/usr/local/lib/python3.5/dist-packages/django/template/loader.py", line 67, in render_to_string
    template = get_template(template_name, using=using)
  File "/usr/local/lib/python3.5/dist-packages/django/template/loader.py", line 25, in get_template
    raise TemplateDoesNotExist(template_name, chain=chain)
django.template.exceptions.TemplateDoesNotExist: index.html
